Workbook

Sheet db
A1: date | B1: gdp_yoy | C1: ftsemib_yoy | D1: ip_yoy | E1: hicp_yoy | F1: esi_yoy | G1: euribor
A2: 1997-Q1 | B2: 0.0027851692 | D2: -0.012356575 | E2: 0.024464832 | F2: 0.022677396 | G2: 2.64
A3: 1997-Q2 | B3: 0.017555468 | D3: 0.036936937 | E3: 0.01754386 | F3: 0.14635078 | G3: 2.96
A4: 1997-Q3 | B4: 0.020042934 | D4: 0.055054152 | E4: 0.015681544 | F4: 0.18575159 | G4: 2.7233333
A5: 1997-Q4 | B5: 0.038612477 | D5: 0.075386013 | E5: 0.018007203 | F5: 0.11585154 | G5: 2.9
A6: 1998-Q1 | B6: 0.03077892 | D6: 0.050044683 | E6: 0.020298507 | F6: 0.20922747 | G6: 3.1033333
A7: 1998-Q2 | B7: 0.020046738 | D7: 0.024326672 | E7: 0.020808561 | F7: 0.10766667 | G7: 2.7233333
A8: 1998-Q3 | B8: 0.01674525 | D8: 0 | E8: 0.021971496 | F8: 0.0031456433 | G8: 2.8033333
A9: 1998-Q4 | B9: -0.0014456054 | D9: -0.022804054 | E9: 0.017688679 | F9: -0.035125894 | G9: 2.79
A10: 1999-Q1 | B10: 0.0079432653 | C10: 0.071595087 | D10: -0.016170213 | E10: 0.012873025 | F10: -0.17894114 | G10: 2.2907319
A11: 1999-Q2 | B11: 0.0063849073 | C11: 0.080744748 | D11: -0.025445293 | E11: 0.01456028 | F11: -0.13782726 | G11: 1.6673629
A12: 1999-Q3 | B12: 0.015981849 | C12: 0.32489699 | D12: 0.00427716 | E12: 0.017431726 | F12: -0.022891188 | G12: 1.5993939
A13: 1999-Q4 | B13: 0.034904502 | C13: 0.20264488 | D13: 0.030250648 | E13: 0.0202781 | F13: 0.086984536 | G13: 1.929798
A14: 2000-Q1 | B14: 0.04257349 | C14: 0.19045184 | D14: 0.033737024 | E14: 0.024263432 | F14: 0.29430836 | G14: 1.6089828
A15: 2000-Q2 | B15: 0.045044243 | C15: 0.25189084 | D15: 0.059181897 | E15: 0.025258324 | F15: 0.28446771 | G15: 2.3963502
A16: 2000-Q3 | B16: 0.043293011 | C16: 0.28827511 | D16: 0.035775128 | E16: 0.0256996 | F16: 0.11970475 | G16: 2.5709338
A17: 2000-Q4 | B17: 0.037470455 | C17: 0.024799619 | D17: 0.040268456 | E17: 0.027825099 | F17: 0.034084173 | G17: 2.5574617
A18: 2001-Q1 | B18: 0.033724145 | C18: -0.14089895 | D18: 0.019246862 | E18: 0.020304569 | F18: -0.062343446 | G18: 2.6783879
A19: 2001-Q2 | B19: 0.026291613 | C19: -0.19663764 | D19: -0.011503698 | E19: 0.028555431 | F19: -0.14619565 | G19: 1.6907511
A20: 2001-Q3 | B20: 0.01296531 | C20: -0.37801548 | D20: -0.022203947 | E20: 0.022271715 | F20: -0.10060189 | G20: 1.9345027
A21: 2001-Q4 | B21: 0.0018318935 | C21: -0.25982234 | D21: -0.056451613 | E21: 0.022651934 | F21: -0.1977644 | G21: 1.3434801
... A117: 2025-Q4 | B117: 0.0083811622 | C117: 0.31469892 | D117: 0.011827957 | E117: 0.01208865 | F117: 0.025303644 | G117: 0.00817
A118: 2026-Q1 | E118: 0.01346348 | F118: 0.027946128 | G118: -0.139645

Sheet db_
A1: date | B1: gdp_yoy | C1: ftsemib_yoy | D1: ip_yoy | E1: hicp_yoy | F1: esi_yoy | G1: euribor
A2: 1997-Q1 | B2: =100*db!B2 -> 0.27851692 | C2: =100*db!C2 -> 0 | D2: =100*db!D2 -> -1.2356575 | E2: =100*db!E2 -> 2.4464832 | F2: =100*db!F2 -> 2.2677396 | G2: =db!G2 -> 2.64
A3: 1997-Q2 | B3: =100*db!B3 -> 1.7555468 | C3: =100*db!C3 -> 0 | D3: =100*db!D3 -> 3.6936937 | E3: =100*db!E3 -> 1.754386 | F3: =100*db!F3 -> 14.635078 | G3: =db!G3 -> 2.96
A4: 1997-Q3 | B4: =100*db!B4 -> 2.0042934 | C4: =100*db!C4 -> 0 | D4: =100*db!D4 -> 5.5054152 | E4: =100*db!E4 -> 1.5681544 | F4: =100*db!F4 -> 18.575159 | G4: =db!G4 -> 2.7233333
A5: 1997-Q4 | B5: =100*db!B5 -> 3.8612477 | C5: =100*db!C5 -> 0 | D5: =100*db!D5 -> 7.5386013 | E5: =100*db!E5 -> 1.8007203 | F5: =100*db!F5 -> 11.585154 | G5: =db!G5 -> 2.9
A6: 1998-Q1 | B6: =100*db!B6 -> 3.077892 | C6: =100*db!C6 -> 0 | D6: =100*db!D6 -> 5.0044683 | E6: =100*db!E6 -> 2.0298507 | F6: =100*db!F6 -> 20.922747 | G6: =db!G6 -> 3.1033333
A7: 1998-Q2 | B7: =100*db!B7 -> 2.0046738 | C7: =100*db!C7 -> 0 | D7: =100*db!D7 -> 2.4326672 | E7: =100*db!E7 -> 2.0808561 | F7: =100*db!F7 -> 10.766667 | G7: =db!G7 -> 2.7233333
A8: 1998-Q3 | B8: =100*db!B8 -> 1.674525 | C8: =100*db!C8 -> 0 | D8: =100*db!D8 -> 0 | E8: =100*db!E8 -> 2.1971496 | F8: =100*db!F8 -> 0.31456433 | G8: =db!G8 -> 2.8033333
A9: 1998-Q4 | B9: =100*db!B9 -> -0.14456054 | C9: =100*db!C9 -> 0 | D9: =100*db!D9 -> -2.2804054 | E9: =100*db!E9 -> 1.7688679 | F9: =100*db!F9 -> -3.5125894 | G9: =db!G9 -> 2.79
A10: 1999-Q1 | B10: =100*db!B10 -> 0.79432653 | C10: =100*db!C10 -> 7.1595087 | D10: =100*db!D10 -> -1.6170213 | E10: =100*db!E10 -> 1.2873025 | F10: =100*db!F10 -> -17.894114 | G10: =db!G10 -> 2.2907319
A11: 1999-Q2 | B11: =100*db!B11 -> 0.63849073 | C11: =100*db!C11 -> 8.0744748 | D11: =100*db!D11 -> -2.5445293 | E11: =100*db!E11 -> 1.456028 | F11: =100*db!F11 -> -13.782726 | G11: =db!G11 -> 1.6673629
A12: 1999-Q3 | B12: =100*db!B12 -> 1.5981849 | C12: =100*db!C12 -> 32.489699 | D12: =100*db!D12 -> 0.427716 | E12: =100*db!E12 -> 1.7431726 | F12: =100*db!F12 -> -2.2891188 | G12: =db!G12 -> 1.5993939
A13: 1999-Q4 | B13: =100*db!B13 -> 3.4904502 | C13: =100*db!C13 -> 20.264488 | D13: =100*db!D13 -> 3.0250648 | E13: =100*db!E13 -> 2.02781 | F13: =100*db!F13 -> 8.6984536 | G13: =db!G13 -> 1.929798
... A118: 2026-Q1 | B118: =100*db!B118 -> 0 | C118: =100*db!C118 -> 0 | D118: =100*db!D118 -> 0 | E118: =100*db!E118 -> 1.346348 | F118: =100*db!F118 -> 2.7946128 | G118: =db!G118 -> -0.139645

Sheet gdp
B1: gdp | C1: gdp y/y
A2: 1996-Q1 | B2: 96.583
A3: 1996-Q2 | B3: 96.722
A4: 1996-Q3 | B4: 96.892
A5: 1996-Q4 | B5: 96.575
A6: 1997-Q1 | B6: 96.852 | C6: =(B6-B2)/B2 -> 0.0027851692
A7: 1997-Q2 | B7: 98.42 | C7: =(B7-B3)/B3 -> 0.017555468
A8: 1997-Q3 | B8: 98.834 | C8: =(B8-B4)/B4 -> 0.020042934
A9: 1997-Q4 | B9: 100.304 | C9: =(B9-B5)/B5 -> 0.038612477
A10: 1998-Q1 | B10: 99.833 | C10: =(B10-B6)/B6 -> 0.03077892
A11: 1998-Q2 | B11: 100.393 | C11: =(B11-B7)/B7 -> 0.020046738
A12: 1998-Q3 | B12: 100.489 | C12: =(B12-B8)/B8 -> 0.01674525
A13: 1998-Q4 | B13: 100.159 | C13: =(B13-B9)/B9 -> -0.0014456054
A14: 1999-Q1 | B14: 100.626 | C14: =(B14-B10)/B10 -> 0.0079432653
A15: 1999-Q2 | B15: 101.034 | C15: =(B15-B11)/B11 -> 0.0063849073
A16: 1999-Q3 | B16: 102.095 | C16: =(B16-B12)/B12 -> 0.015981849
A17: 1999-Q4 | B17: 103.655 | C17: =(B17-B13)/B13 -> 0.034904502
... A121: 2025-Q4 | B121: 117.187 | C121: =(B121-B117)/B117 -> 0.0083811622

Sheet ftse_mib
A1: Date | B1: Price | C1: CVol | D1: Change | E1: % Change | F1: Total Return (Gross, Unhedged) | G1: Cumulative Return % (Gross, Unhedged) | H1: Open | I1: High | J1: Low
A2: 35886 | B2: 35582.33 | D2: 11180.79 | E2: 45.820018 | F2: 35587.21 | G2: 45.840017 | I2: 35582.33 | J2: 24913.97
A3: 35977 | B3: 34330.53 | D3: -1251.8 | E3: -3.5180383 | F3: 34708.75 | G3: 42.239998 | I3: 37436.84 | J3: 31136.37
A4: 36069 | B4: 26609.88 | D4: -7720.65 | E4: -22.489166 | F4: 26956.38 | G4: 10.469995 | I4: 38766.73 | J4: 26609.88
A5: 36159 | B5: 35426.16 | D5: 8816.28 | E5: 33.131604 | F5: 35894.67 | G5: 47.100019 | I5: 35460.32 | J5: 24860.29
A6: 36251 | B6: 38129.85 | C6: =(B6-B2)/B2 -> 0.071595087 | D6: 2703.69 | E6: 7.6319025 | F6: 38678.88 | G6: 58.509996 | I6: 38600.8 | J6: 33449.63
A7: 36342 | B7: 37102.54 | C7: =(B7-B3)/B3 -> 0.080744748 | D7: -1027.31 | E7: -2.6942409 | F7: 38059.08 | G7: 55.969992 | I7: 38749.65 | J7: 35928.83
A8: 36434 | B8: 35255.35 | C8: =(B8-B4)/B4 -> 0.32489699 | D8: -1847.19 | E8: -4.9786079 | F8: 36309.49 | G8: 48.799994 | I8: 38317.74 | J8: 33044.57
A9: 36524 | B9: 42605.09 | C9: =(B9-B5)/B5 -> 0.20264488 | D9: 7349.74 | E9: 20.847162 | F9: 43886.17 | G9: 79.850001 | I9: 42605.09 | J9: 32873.76
A10: 36616 | B10: 45391.75 | C10: =(B10-B6)/B6 -> 0.19045184 | D10: 2786.66 | E10: 6.5406739 | F10: 46755.79 | G10: 91.609997 | I10: 50108.56 | J10: 38835.05
A11: 36707 | B11: 46448.33 | C11: =(B11-B7)/B7 -> 0.25189084 | D11: 1056.58 | E11: 2.3276917 | F11: 48688.39 | G11: 99.529989 | I11: 46772.87 | J11: 42651.45
A12: 36798 | B12: 45418.59 | C12: =(B12-B8)/B8 -> 0.28827511 | D12: -1029.74 | E12: -2.2169581 | F12: 47729.41 | G12: 95.599991 | I12: 48634.71 | J12: 45142.85
A13: 36889 | B13: 43661.68 | C13: =(B13-B9)/B9 -> 0.024799619 | D13: -1756.91 | E13: -3.8682619 | F13: 45889.54 | G13: 88.060016 | I13: 48437.06 | J13: 42941.83
A14: 36980 | B14: 38996.1 | C14: =(B14-B10)/B10 -> -0.14089895 | D14: -4665.58 | E14: -10.685755 | F14: 40984.83 | G14: 67.960014 | I14: 45067.21 | J14: 35919.07
A15: 37071 | B15: 37314.84 | C15: =(B15-B11)/B11 -> -0.19663764 | D15: -1681.26 | E15: -4.3113542 | F15: 39884.32 | G15: 63.450012 | I15: 41123.92 | J15: 36402.22
A16: 37165 | B16: 28249.66 | C16: =(B16-B12)/B12 -> -0.37801548 | D16: -9065.18 | E16: -24.293766 | F16: 30194.47 | G16: 23.740018 | I16: 38129.85 | J16: 23896.43
A17: 37253 | B17: 32317.4 | C17: =(B17-B13)/B13 -> -0.25982234 | D17: 4067.74 | E17: 14.399253 | F17: 34550.14 | G17: 41.589998 | I17: 33364.23 | J17: 28596.17
... A58: 40998 | B58: 15980.07 | C58: =(B58-B54)/B54 -> -0.27256749 | D58: 890.33 | E58: 5.9002342 | F58: 25164.35 | G58: 3.1260732 | I58: 17158.65 | J58: 14401.55
A59: 41089 | B59: 14274.37 | C59: =(B59-B55)/B55 -> -0.30426588 | D59: -1705.7 | E59: -10.673921 | F59: 23196.1 | G59: -4.9400161 | H59: 16455.16 | I59: 16014.39 | J59: 12568.05
A60: 41183 | B60: 15523.1 | C60: =(B60-B56)/B56 -> 0.04628975 | D60: 1248.73 | E60: 8.7480568 | F60: 25347.22 | G60: 3.8754931 | H60: 14494.41 | I60: 16694.79 | J60: 12295.76
A61: 41271 | B61: 16273.38 | C61: =(B61-B57)/B57 -> 0.078440053 | D61: 750.28 | E61: 4.8333129 | F61: 26650.17 | G61: 9.2151151 | H61: 15758.6 | I61: 16503.08 | J61: 14855.79
A62: 41361 | B62: 15338.72 | C62: =(B62-B58)/B58 -> -0.040134367 | D62: -934.66 | E62: -5.7434903 | F62: 25125.93 | G62: 2.9686241 | H62: 16866.61 | I62: 17982.9 | J62: 15197.06
A63: 41456 | B63: 15459.575 | C63: =(B63-B59)/B59 -> 0.083030251 | D63: 120.85452 | E63: 0.78790485 | F63: 25983.823 | G63: 6.4843577 | H63: 15481.8 | I63: 17644.73 | J63: 14901.82
A64: 41548 | B64: 17977.059 | C64: =(B64-B60)/B60 -> 0.15808436 | D64: 2517.4848 | E64: 16.284308 | F64: 30361.287 | G64: 24.423653 | H64: 15359.11 | I64: 18142.98 | J64: 15024.01
A65: 41638 | B65: 18967.71 | C65: =(B65-B61)/B61 -> 0.16556669 | D65: 990.65038 | E65: 5.5106364 | F65: 32113.969 | G65: 31.606321 | H65: 17986.89 | I65: 19501.18 | J65: 17749.71
A66: 41730 | B66: 21915.407 | C66: =(B66-B62)/B62 -> 0.42876374 | D66: 2947.6972 | E66: 15.540607 | F66: 37110.677 | G66: 52.083342 | H66: 19002.98 | I66: 21937.54 | J66: 18790.05
A67: 41821 | B67: 21563.433 | C67: =(B67-B63)/B63 -> 0.39482706 | D67: -351.97398 | E67: -1.6060573 | F67: 37261.686 | G67: 52.702191 | H67: 21047.29 | I67: 22590.18 | J67: 19935.6
A68: 41913 | B68: 20706.314 | C68: =(B68-B64)/B64 -> 0.15181876 | D68: -857.11869 | E68: -3.9748712 | F68: 35948.623 | G68: 47.321123 | H68: 21709.91 | I68: 21896.15 | J68: 18885.58
A69: 42003 | B69: 19011.965 | C69: =(B69-B65)/B65 -> 0.0023331792 | D69: -1694.3495 | E69: -8.1827671 | F69: 33067.058 | G69: 35.512178 | H69: 20679.96 | I69: 20715.84 | J69: 17555.77
A70: 42095 | B70: 23358.992 | C70: =(B70-B66)/B66 -> 0.065870799 | D70: 4347.0275 | E70: 22.864694 | F70: 40643.174 | G70: 66.559871 | H70: 19156.72 | I70: 23447.36 | J70: 17991.76
... A112: 45931 | B112: 43079.58 | C112: =(B112-B108)/B108 -> 0.27563525 | D112: 3518.2831 | E112: 8.8932449 | F112: 113910.13 | G112: 366.81532 | H112: 39860.05 | I112: 43564.12 | J112: 39520.56
B113: 44944.54 | C113: =(B113-B109)/B109 -> 0.31469892

Sheet IP
B1: IP
A2: 1990-Q1 | B2: 105.5
A3: 1990-Q2 | B3: 105.7
A4: 1990-Q3 | B4: 105.5
A5: 1990-Q4 | B5: 104.6
A6: 1991-Q1 | B6: 104.4 | C6: =(B6-B2)/B2 -> -0.01042654
A7: 1991-Q2 | B7: 103.3 | C7: =(B7-B3)/B3 -> -0.022705771
A8: 1991-Q3 | B8: 104.8 | C8: =(B8-B4)/B4 -> -0.0066350711
A9: 1991-Q4 | B9: 104.9 | C9: =(B9-B5)/B5 -> 0.0028680688
A10: 1992-Q1 | B10: 104.9 | C10: =(B10-B6)/B6 -> 0.004789272
A11: 1992-Q2 | B11: 104.8 | C11: =(B11-B7)/B7 -> 0.014520813
A12: 1992-Q3 | B12: 101.9 | C12: =(B12-B8)/B8 -> -0.027671756
A13: 1992-Q4 | B13: 101.2 | C13: =(B13-B9)/B9 -> -0.035271687
A14: 1993-Q1 | B14: 101.7 | C14: =(B14-B10)/B10 -> -0.030505243
A15: 1993-Q2 | B15: 100.7 | C15: =(B15-B11)/B11 -> -0.039122137
A16: 1993-Q3 | B16: 99.8 | C16: =(B16-B12)/B12 -> -0.02060844
A17: 1993-Q4 | B17: 100.6 | C17: =(B17-B13)/B13 -> -0.0059288538
... A145: 2025-Q4 | B145: 94.1 | C145: =(B145-B141)/B141 -> 0.011827957

Sheet hicp
A1: date | B1: hicp
A2: 1996-01 | B2: 54.3 | D2: =AVERAGE(B2:B4) -> 54.5
A3: 1996-02 | B3: 54.5 | D3: =AVERAGE(B5:B7) -> 55.1
A4: 1996-03 | B4: 54.7
A5: 1996-04 | B5: 54.9
A6: 1996-05 | B6: 55.1
A7: 1996-06 | B7: 55.3
A8: 1996-07 | B8: 55.2
A9: 1996-08 | B9: 55.3
A10: 1996-09 | B10: 55.3
A11: 1996-10 | B11: 55.4
A12: 1996-11 | B12: 55.6
A13: 1996-12 | B13: 55.6
A14: 1997-01 | B14: 55.8
A15: 1997-02 | B15: 55.8
... A364: 2026-03 | B364: 101.6

Sheet ESI
B1: IT_ESI
A2: 31078 | B2: 85.3
A3: 31106 | B3: 90.2
A4: 31137 | B4: 81.4
A5: 31167 | B5: 84.7
A6: 31198 | B6: 88.2
A7: 31228 | B7: 86.5
A8: 31259 | B8: 91.7
A9: 31290 | B9: 84.3
A10: 31320 | B10: 93.8
A11: 31351 | B11: 86.7
A12: 31381 | B12: 86.7
A13: 31412 | B13: 82.3
... A133: 35064 | B133: 98
A134: 35095 | B134: 95.6 | C134: =AVERAGE(B134:B136) -> 91.133333
A135: 35124 | B135: 88.6
A136: 35155 | B136: 89.2
A137: 35185 | B137: 86.7
A138: 35216 | B138: 86.5
A139: 35246 | B139: 88.5
A140: 35277 | B140: 89.2
A141: 35308 | B141: 90.3
A142: 35338 | B142: 88.6
A143: 35369 | B143: 99.6
A144: 35399 | B144: 95
A145: 35430 | B145: 93.7
A146: 35461 | B146: 93.1
... A424: 43921 | B424: 80.1
A425: 43951 | B425: NA
A426: 43982 | B426: 56
A427: 44012 | B427: 69.2
A428: 44043 | B428: 78.1
A429: 44074 | B429: 82
A430: 44104 | B430: 92.8
A431: 44135 | B431: 94
A432: 44165 | B432: 83.7
A433: 44196 | B433: 92.3
A434: 44227 | B434: 96.4
A435: 44255 | B435: 99.1
A436: 44286 | B436: 101.6
...

Sheet EURIBOR
A1: TIME PERIOD | B1: Real 3-month Euribor (Euro Interbank Offered Rate)
A2: 1994Jan | B2: 4.01
A3: 1994Feb | B3: 3.96
A4: 1994Mar | B4: 3.95
A5: 1994Apr | B5: 3.87
A6: 1994May | B6: 3.44
A7: 1994Jun | B7: 3.6
A8: 1994Jul | B8: 3.74
A9: 1994Aug | B9: 3.73
A10: 1994Sep | B10: 3.68
A11: 1994Oct | B11: 3.83
A12: 1994Nov | B12: 3.9
A13: 1994Dec | B13: 4.09
... A25: 1995Dec | B25: 3.92
A26: 1996Jan | B26: 3.41 | C26: =AVERAGE(B26:B28) -> 3.23
A27: 1996Feb | B27: 3.18
A28: 1996Mar | B28: 3.1
A29: 1996Apr | B29: 2.87
A30: 1996May | B30: 2.56
A31: 1996Jun | B31: 2.98
A32: 1996Jul | B32: 2.96
A33: 1996Aug | B33: 3.08
A34: 1996Sep | B34: 2.86
A35: 1996Oct | B35: 2.69
A36: 1996Nov | B36: 2.67
A37: 1996Dec | B37: 2.6
A38: 1997Jan | B38: 2.39
... A387: 2026Mar | B387: -0.39059

Sheet monthly to quarterly
A1: date | B1: hicp | C1: ESI | D1: EURIBOR | G1: hicp_yoy | H1: esi_yoy
A2: 1996-Q1 | B2: 54.5 | C2: 91.133333 | D2: 3.23 | F2: 1997-Q1 | G2: =(B6-B2)/B2 -> 0.024464832 | H2: =(C6-C2)/C2 -> 0.022677396
A3: 1996-Q2 | B3: 55.1 | C3: 87.233333 | D3: 2.8033333 | F3: 1997-Q2 | G3: =(B7-B3)/B3 -> 0.01754386 | H3: =(C7-C3)/C3 -> 0.14635078
A4: 1996-Q3 | B4: 55.266667 | C4: 89.366667 | D4: 2.9666667 | F4: 1997-Q3 | G4: =(B8-B4)/B4 -> 0.015681544 | H4: =(C8-C4)/C4 -> 0.18575159
A5: 1996-Q4 | B5: 55.533333 | C5: 96.1 | D5: 2.6533333 | F5: 1997-Q4 | G5: =(B9-B5)/B5 -> 0.018007203 | H5: =(C9-C5)/C5 -> 0.11585154
A6: 1997-Q1 | B6: 55.833333 | C6: 93.2 | D6: 2.64 | F6: 1998-Q1 | G6: =(B10-B6)/B6 -> 0.020298507 | H6: =(C10-C6)/C6 -> 0.20922747
A7: 1997-Q2 | B7: 56.066667 | C7: 100 | D7: 2.96 | F7: 1998-Q2 | G7: =(B11-B7)/B7 -> 0.020808561 | H7: =(C11-C7)/C7 -> 0.10766667
A8: 1997-Q3 | B8: 56.133333 | C8: 105.96667 | D8: 2.7233333 | F8: 1998-Q3 | G8: =(B12-B8)/B8 -> 0.021971496 | H8: =(C12-C8)/C8 -> 0.0031456433
A9: 1997-Q4 | B9: 56.533333 | C9: 107.23333 | D9: 2.9 | F9: 1998-Q4 | G9: =(B13-B9)/B9 -> 0.017688679 | H9: =(C13-C9)/C9 -> -0.035125894
A10: 1998-Q1 | B10: 56.966667 | C10: 112.7 | D10: 3.1033333 | F10: 1999-Q1 | G10: =(B14-B10)/B10 -> 0.012873025 | H10: =(C14-C10)/C10 -> -0.17894114
A11: 1998-Q2 | B11: 57.233333 | C11: 110.76667 | D11: 2.7233333 | F11: 1999-Q2 | G11: =(B15-B11)/B11 -> 0.01456028 | H11: =(C15-C11)/C11 -> -0.13782726
A12: 1998-Q3 | B12: 57.366667 | C12: 106.3 | D12: 2.8033333 | F12: 1999-Q3 | G12: =(B16-B12)/B12 -> 0.017431726 | H12: =(C16-C12)/C12 -> -0.022891188
A13: 1998-Q4 | B13: 57.533333 | C13: 103.46667 | D13: 2.79 | F13: 1999-Q4 | G13: =(B17-B13)/B13 -> 0.0202781 | H13: =(C17-C13)/C13 -> 0.086984536
... A118: 2025-Q1 | B118: 99.033333 | C118: 99 | D118: 0.223503 | F118: 2026-Q1 | G118: =(B122-B118)/B118 -> 0.01346348 | H118: =(C122-C118)/C118 -> 0.027946128
A119: 2025-Q2 | B119: 100.5 | C119: 97.933333 | D119: 0.074357833
A120: 2025-Q3 | B120: 99.966667 | C120: 99.2 | D120: -0.055094767
A121: 2025-Q4 | B121: 100.46667 | C121: 101.3 | D121: 0.00817
A122: 2026-Q1 | B122: 100.36667 | C122: 101.76667 | D122: -0.139645
